Workbook

Sheet Eingabe
A1: ⚓ Bordkasse
A2: Ausgabe erfassen
A4: 1. Details
B5: Datum
B8: Beschreibung
B11: Kategorie (antippen für Auswahl)
B14: Bezahlt von (antippen für Auswahl)
B17: Betrag (€)
B20: Alkohol-Anteil (€) · optional
A23: 2. Aufteilung
B24: Wie aufteilen?
B25: Gleichmäßig
B26: ► Gleichmäßig — alle zahlen gleich viel ► An Bord — nur wer an dem Tag da war ► Zeitanteilig — nach Anwesenheitstagen ► Individuell — nur unten markierte Personen
A28: Nur bei 'Individuell': Wer ist dabei?
B29: Pro Person auf das Feld tippen und 'x' eingeben (oder leer lassen)
B30: Person x = dabei
B31: =IFERROR(IF(Besatzung!B11="","P1 (leer)",Besatzung!B11),"P1")
B32: =IFERROR(IF(Besatzung!B12="","P2 (leer)",Besatzung!B12),"P2")
B33: =IFERROR(IF(Besatzung!B13="","P3 (leer)",Besatzung!B13),"P3")
B34: =IFERROR(IF(Besatzung!B14="","P4 (leer)",Besatzung!B14),"P4")
B35: =IFERROR(IF(Besatzung!B15="","P5 (leer)",Besatzung!B15),"P5")
B36: =IFERROR(IF(Besatzung!B16="","P6 (leer)",Besatzung!B16),"P6")
B37: =IFERROR(IF(Besatzung!B17="","P7 (leer)",Besatzung!B17),"P7")
B38: =IFERROR(IF(Besatzung!B18="","P8 (leer)",Besatzung!B18),"P8")
B39: =IFERROR(IF(Besatzung!B19="","P9 (leer)",Besatzung!B19),"P9")
B40: =IFERROR(IF(Besatzung!B20="","P10 (leer)",Besatzung!B20),"P10")
B41: =IFERROR(IF(Besatzung!B21="","P11 (leer)",Besatzung!B21),"P11")
B42: =IFERROR(IF(Besatzung!B22="","P12 (leer)",Besatzung!B22),"P12")
A45: ▶ SPEICHERN
A46: Tippe hier (Desktop) oder nutze Menü: ⚓ Bordkasse → 💾 Speichern (Mobile)
A48: Zuletzt erfasst
B49: =IFERROR("Letzte: "&TEXT(Transaktionen!B203,"TT.MM.JJJJ")&" · "&Transaktionen!D203&" · "&TEXT(Transaktionen!G203,"#,##0.00 €"),"(noch keine Transaktionen erfasst)")

Sheet Gutschrift
A1: ⚓ Bordkasse
A2: Gutschrift erfassen
A4: 1. Details
B5: Datum
B8: Beschreibung (optional)
B11: Betrag (€)
A14: 2. Wer hat wem gezahlt?
B15: Zahlt (Von)
B18: Empfängt (An)
B20: Name eines Crewmitglieds oder 'Alle' (Aufteilung an gesamte Crew)
A22: ▶ GUTSCHRIFT SPEICHERN
A23: Tippe hier (Desktop) oder nutze Menü: ⚓ Bordkasse → 💾 Gutschrift speichern

Sheet Besatzung
A1: ⚓ Besatzung & Törn-Daten
A3: Törn-Informationen
A4: Törn-Name: | B4: Mein Törn
A5: Start-Datum: | B5: 46153 | G5: 1. Törntag
A6: End-Datum: | B6: 46160 | G6: Letzter Törntag
A7: Gesamttage: | B7: =IFERROR(B6-B5+1,0) | G7: Automatisch berechnet
A9: Besatzung (bis zu 12 Personen)
A10: Nr. | B10: Name | C10: An Bord ab | D10: An Bord bis | E10: Tage | F10: Alkohol? (x) | G10: Zeitanteil % | H10: Hinweis
A11: P1 | B11: Skipper | C11: =$B$5 | D11: =$B$6 | E11: =IFERROR(IF(B11="","",MIN(IF(D11="",Besatzung!$B$6,D11),Besatzung!$B$6)-MAX(IF(C11="",Besatzung!$B$5,C11),Besatzung!$B$5)+1),"") | G11: =IFERROR(IF(B11="","",E11/SUM($E$11:$E$22)),"") | H11: ⚓ Pflichtfeld | K11: Alle
A12: P2 | B12: Crew 2 | C12: =$B$5 | D12: =$B$6 | E12: =IFERROR(IF(B12="","",MIN(IF(D12="",Besatzung!$B$6,D12),Besatzung!$B$6)-MAX(IF(C12="",Besatzung!$B$5,C12),Besatzung!$B$5)+1),"") | G12: =IFERROR(IF(B12="","",E12/SUM($E$11:$E$22)),"") | K12: =IFERROR(B11,"")
A13: P3 | B13: Crew 3 | C13: =$B$5 | D13: =$B$6 | E13: =IFERROR(IF(B13="","",MIN(IF(D13="",Besatzung!$B$6,D13),Besatzung!$B$6)-MAX(IF(C13="",Besatzung!$B$5,C13),Besatzung!$B$5)+1),"") | G13: =IFERROR(IF(B13="","",E13/SUM($E$11:$E$22)),"") | H13: Leer = gesamter Törn | K13: =IFERROR(B12,"")
A14: P4 | B14: Crew 4 | C14: =$B$5 | D14: =$B$6 | E14: =IFERROR(IF(B14="","",MIN(IF(D14="",Besatzung!$B$6,D14),Besatzung!$B$6)-MAX(IF(C14="",Besatzung!$B$5,C14),Besatzung!$B$5)+1),"") | G14: =IFERROR(IF(B14="","",E14/SUM($E$11:$E$22)),"") | H14: Leer = gesamter Törn | K14: =IFERROR(B13,"")
A15: P5 | B15: Crew 5 | C15: 46156 | D15: =$B$6 | E15: =IFERROR(IF(B15="","",MIN(IF(D15="",Besatzung!$B$6,D15),Besatzung!$B$6)-MAX(IF(C15="",Besatzung!$B$5,C15),Besatzung!$B$5)+1),"") | G15: =IFERROR(IF(B15="","",E15/SUM($E$11:$E$22)),"") | K15: =IFERROR(B14,"")
A16: P6 | E16: =IFERROR(IF(B16="","",MIN(IF(D16="",Besatzung!$B$6,D16),Besatzung!$B$6)-MAX(IF(C16="",Besatzung!$B$5,C16),Besatzung!$B$5)+1),"") | G16: =IFERROR(IF(B16="","",E16/SUM($E$11:$E$22)),"") | K16: =IFERROR(B15,"")
A17: P7 | E17: =IFERROR(IF(B17="","",MIN(IF(D17="",Besatzung!$B$6,D17),Besatzung!$B$6)-MAX(IF(C17="",Besatzung!$B$5,C17),Besatzung!$B$5)+1),"") | G17: =IFERROR(IF(B17="","",E17/SUM($E$11:$E$22)),"")
A18: P8 | E18: =IFERROR(IF(B18="","",MIN(IF(D18="",Besatzung!$B$6,D18),Besatzung!$B$6)-MAX(IF(C18="",Besatzung!$B$5,C18),Besatzung!$B$5)+1),"") | G18: =IFERROR(IF(B18="","",E18/SUM($E$11:$E$22)),"") | K18: =IFERROR(B17,"")
A19: P9 | E19: =IFERROR(IF(B19="","",MIN(IF(D19="",Besatzung!$B$6,D19),Besatzung!$B$6)-MAX(IF(C19="",Besatzung!$B$5,C19),Besatzung!$B$5)+1),"") | G19: =IFERROR(IF(B19="","",E19/SUM($E$11:$E$22)),"") | K19: =IFERROR(B18,"")
A20: P10 | E20: =IFERROR(IF(B20="","",MIN(IF(D20="",Besatzung!$B$6,D20),Besatzung!$B$6)-MAX(IF(C20="",Besatzung!$B$5,C20),Besatzung!$B$5)+1),"") | G20: =IFERROR(IF(B20="","",E20/SUM($E$11:$E$22)),"") | K20: =IFERROR(B19,"")
A21: P11 | E21: =IFERROR(IF(B21="","",MIN(IF(D21="",Besatzung!$B$6,D21),Besatzung!$B$6)-MAX(IF(C21="",Besatzung!$B$5,C21),Besatzung!$B$5)+1),"") | G21: =IFERROR(IF(B21="","",E21/SUM($E$11:$E$22)),"") | K21: =IFERROR(B20,"")
A22: P12 | E22: =IFERROR(IF(B22="","",MIN(IF(D22="",Besatzung!$B$6,D22),Besatzung!$B$6)-MAX(IF(C22="",Besatzung!$B$5,C22),Besatzung!$B$5)+1),"") | G22: =IFERROR(IF(B22="","",E22/SUM($E$11:$E$22)),"") | K22: =IFERROR(B21,"")
K23: =IFERROR(B22,"")
A24: 💡 Alkohol-Spalte: x = Person trinkt Alkohol auf diesem Törn. Wird automatisch für alle Ausgaben berücksichtigt. Zeitanteil % berechnet sich automatisch aus den Bord-Tagen. Bord-Daten leer lassen = gesamter Törn. Beispiel: A 5 Tage, B 3 Tage → A trägt 62,5 % der zeitanteiligen Kosten, B 37,5 %.

Sheet Kategorien
A1: ⚓ Kategorien
A2: Hier Kategorien verwalten — werden automatisch in Eingabe, Transaktionen und Auswertung übernommen
A3: Nr. | B3: Kategorie | C3: Empfohlene Aufteilung (nur Hinweis)
A4: 1 | B4: Lebensmittel & Getränke | C4: Gleichmäßig oder An Bord
A5: 2 | B5: Restaurants | C5: An Bord (nur Anwesende)
A6: 3 | B6: Versicherungen | C6: Zeitanteilig
A7: 4 | B7: Hafen- & Brückengebühren | C7: An Bord (nur Anwesende)
A8: 5 | B8: Sprit | C8: Zeitanteilig
A9: 6 | B9: Kaution | C9: Zeitanteilig
A10: 7 | B10: Schwimmwesten | C10: Individuell (x setzen)
A11: 8 | B11: Spaßaddons | C11: Individuell oder Gleichmäßig
A12: 9 | B12: Sonstiges | C12: Gleichmäßig
A13: 10 | B13: ← neue Kategorie hier eintragen
A14: 11 | B14: ← neue Kategorie hier eintragen
A15: 12 | B15: ← neue Kategorie hier eintragen
A16: 13 | B16: ← neue Kategorie hier eintragen
A17: 14 | B17: ← neue Kategorie hier eintragen
A18: 15 | B18: ← neue Kategorie hier eintragen
A19: 16 | B19: ← neue Kategorie hier eintragen
A20: 17 | B20: ← neue Kategorie hier eintragen
A21: 18 | B21: ← neue Kategorie hier eintragen
A22: 19 | B22: ← neue Kategorie hier eintragen
A23: 20 | B23: ← neue Kategorie hier eintragen

Sheet Transaktionen
A1: ⚓ Transaktionen — Wird automatisch durch das Apps Script befüllt
A2: # | B2: Datum | C2: Typ | D2: Beschreibung | E2: Kategorie | F2: Bezahlt von | G2: Betrag € | H2: Alkohol € | I2: Aufteilung | J2: =IFERROR(LEFT(Besatzung!C11,5),"P1") | K2: =IFERROR(LEFT(Besatzung!C12,5),"P2") | L2: =IFERROR(LEFT(Besatzung!C13,5),"P3") | M2: =IFERROR(LEFT(Besatzung!C14,5),"P4") | N2: =IFERROR(LEFT(Besatzung!C15,5),"P5") | O2: =IFERROR(LEFT(Besatzung!C16,5),"P6") | P2: =IFERROR(LEFT(Besatzung!C17,5),"P7") | Q2: =IFERROR(LEFT(Besatzung!C18,5),"P8") | R2: =IFERROR(LEFT(Besatzung!C19,5),"P9") | S2: =IFERROR(LEFT(Besatzung!C20,5),"P10") | T2: =IFERROR(LEFT(Besatzung!C21,5),"P11") | U2: =IFERROR(LEFT(Besatzung!C22,5),"P12") | V2: P1 Anteil | W2: P2 Anteil | X2: P3 Anteil | Y2: P4 Anteil | Z2: P5 Anteil | AA2: P6 Anteil | AB2: P7 Anteil | AC2: P8 Anteil | AD2: P9 Anteil | AE2: P10 Anteil | AF2: P11 Anteil | AG2: P12 Anteil | AH2: Gut-Von | AI2: Gut-An
A4: =IF(AND(D4="",C4=""),"",1) | V4: =IF(C4="Gutschrift","",IF(G4="","",IF(Besatzung!$B$11="","",IFERROR(IF(I4="Zeitanteilig",(Besatzung!$G$11*(G4-IFERROR(H4,0))+((Besatzung!$B$11<>"")*IF(B4="",1,(IF(Besatzung!$C$11="",Besatzung!$B$5,Besatzung!$C$11)<=B4)*(IF(Besatzung!$D$11="",Besatzung!$B$6,Besatzung!$D$11)>=B4)))*(Besatzung!$F$11="x")*IFERROR(H4,0)/IFERROR(SUMPRODUCT((Besatzung!$B$11:$B$22<>"")*(Besatzung!$F$11:$F$22="x")*(IF(Besatzung!$C$11:$C$22="",Besatzung!$B$5,Besatzung!$C$11:$C$22)<=B4)*(IF(Besatzung!$D$11:$D$22="",Besatzung!$B$6,Besatzung!$D$11:$D$22)>=B4)),1)),IF(I4="An Bord",(((Besatzung!$B$11<>"")*IF(B4="",1,(IF(Besatzung!$C$11="",Besatzung!$B$5,Besatzung!$C$11)<=B4)*(IF(Besatzung!$D$11="",Besatzung!$B$6,Besatzung!$D$11)>=B4)))*((G4-IFERROR(H4,0))/IFERROR(SUMPRODUCT((Besatzung!$B$11:$B$22<>"")*(IF(Besatzung!$C$11:$C$22="",Besatzung!$B$5,Besatzung!$C$11:$C$22)<=B4)*(IF(Besatzung!$D$11:$D$22="",Besatzung!$B$6,Besatzung!$D$11:$D$22)>=B4)),1)+(Besatzung!$F$11="x")*IFERROR(H4,0)/IFERROR(SUMPRODUCT((Besatzung!$B$11:$B$22<>"")*(Besatzung!$F$11:$F$22="x")*(IF(Besatzung!$C$11:$C$22="",Besatzung!$B$5,Besatzung!$C$11:$C$22)<=B4)*(IF(Besatzung!$D$11:$D$22="",Besatzung!$B$6,Besatzung!$D$11:$D$22)>=B4)),1))),IF(I4="Individuell",((J4="x")*((G4-IFERROR(H4,0))/IFERROR(COUNTIF(J4:U4,"x"),1)+(Besatzung!$F$11="x")*IFERROR(H4,0)/IFERROR(SUMPRODUCT((J4:U4="x")*(Besatzung!$F$11:$F$22="x")),1))),(IF(COUNTIF(J4:U4,"x")=0,IF(Besatzung!$B$11<>"",1,0),(J4="x"))*(G4-IFERROR(H4,0))/IFERROR(IF(COUNTIF(J4:U4,"x")=0,COUNTA(Besatzung!$B$11:$B$22),COUNTIF(J4:U4,"x")),1)+IF(COUNTIF(J4:U4,"x")=0,(Besatzung!$F$11="x"),(J4="x")*(Besatzung!$F$11="x"))*IFERROR(H4,0)/IFERROR(IF(COUNTIF(J4:U4,"x")=0,SUMPRODUCT((Besatzung!$B$11:$B$22<>"")*(Besatzung!$F$11:$F$22="x")),SUMPRODUCT((J4:U4="x")*(Besatzung!$F$11:$F$22="x"))),1))))),0)))) | W4: =IF(C4="Gutschrift","",IF(G4="","",IF(Besatzung!$B$12="","",IFERROR(IF(I4="Zeitanteilig",(Besatzung!$G$12*(G4-IFERROR(H4,0))+((Besatzung!$B$12<>"")*IF(B4="",1,(IF(Besatzung!$C$12="",Besatzung!$B$5,Besatzung!$C$12)<=B4)*(IF(Besatzung!$D$12="",Besatzung!$B$6,Besatzung!$D$12)>=B4)))*(Besatzung!$F$12="x")*IFERROR(H4,0)/IFERROR(SUMPRODUCT((Besatzung!$B$11:$B$22<>"")*(Besatzung!$F$11:$F$22="x")*(IF(Besatzung!$C$11:$C$22="",Besatzung!$B$5,Besatzung!$C$11:$C$22)<=B4)*(IF(Besatzung!$D$11:$D$22="",Besatzung!$B$6,Besatzung!$D$11:$D$22)>=B4)),1)),IF(I4="An Bord",(((Besatzung!$B$12<>"")*IF(B4="",1,(IF(Besatzung!$C$12="",Besatzung!$B$5,Besatzung!$C$12)<=B4)*(IF(Besatzung!$D$12="",Besatzung!$B$6,Besatzung!$D$12)>=B4)))*((G4-IFERROR(H4,0))/IFERROR(SUMPRODUCT((Besatzung!$B$11:$B$22<>"")*(IF(Besatzung!$C$11:$C$22="",Besatzung!$B$5,Besatzung!$C$11:$C$22)<=B4)*(IF(Besatzung!$D$11:$D$22="",Besatzung!$B$6,Besatzung!$D$11:$D$22)>=B4)),1)+(Besatzung!$F$12="x")*IFERROR(H4,0)/IFERROR(SUMPRODUCT((Besatzung!$B$11:$B$22<>"")*(Besatzung!$F$11:$F$22="x")*(IF(Besatzung!$C$11:$C$22="",Besatzung!$B$5,Besatzung!$C$11:$C$22)<=B4)*(IF(Besatzung!$D$11:$D$22="",Besatzung!$B$6,Besatzung!$D$11:$D$22)>=B4)),1))),IF(I4="Individuell",((K4="x")*((G4-IFERROR(H4,0))/IFERROR(COUNTIF(J4:U4,"x"),1)+(Besatzung!$F$12="x")*IFERROR(H4,0)/IFERROR(SUMPRODUCT((J4:U4="x")*(Besatzung!$F$11:$F$22="x")),1))),(IF(COUNTIF(J4:U4,"x")=0,IF(Besatzung!$B$12<>"",1,0),(K4="x"))*(G4-IFERROR(H4,0))/IFERROR(IF(COUNTIF(J4:U4,"x")=0,COUNTA(Besatzung!$B$11:$B$22),COUNTIF(J4:U4,"x")),1)+IF(COUNTIF(J4:U4,"x")=0,(Besatzung!$F$12="x"),(K4="x")*(Besatzung!$F$12="x"))*IFERROR(H4,0)/IFERROR(IF(COUNTIF(J4:U4,"x")=0,SUMPRODUCT((Besatzung!$B$11:$B$22<>"")*(Besatzung!$F$11:$F$22="x")),SUMPRODUCT((J4:U4="x")*(Besatzung!$F$11:$F$22="x"))),1))))),0)))) | X4: =IF(C4="Gutschrift","",IF(G4="","",IF(Besatzung!$B$13="","",IFERROR(IF(I4="Zeitanteilig",(Besatzung!$G$13*(G4-IFERROR(H4,0))+((Besatzung!$B$13<>"")*IF(B4="",1,(IF(Besatzung!$C$13="",Besatzung!$B$5,Besatzung!$C$13)<=B4)*(IF(Besatzung!$D$13="",Besatzung!$B$6,Besatzung!$D$13)>=B4)))*(Besatzung!$F$13="x")*IFERROR(H4,0)/IFERROR(SUMPRODUCT((Besatzung!$B$11:$B$22<>"")*(Besatzung!$F$11:$F$22="x")*(IF(Besatzung!$C$11:$C$22="",Besatzung!$B$5,Besatzung!$C$11:$C$22)<=B4)*(IF(Besatzung!$D$11:$D$22="",Besatzung!$B$6,Besatzung!$D$11:$D$22)>=B4)),1)),IF(I4="An Bord",(((Besatzung!$B$13<>"")*IF(B4="",1,(IF(Besatzung!$C$13="",Besatzung!$B$5,Besatzung!$C$13)<=B4)*(IF(Besatzung!$D$13="",Besatzung!$B$6,Besatzung!$D$13)>=B4)))*((G4-IFERROR(H4,0))/IFERROR(SUMPRODUCT((Besatzung!$B$11:$B$22<>"")*(IF(Besatzung!$C$11:$C$22="",Besatzung!$B$5,Besatzung!$C$11:$C$22)<=B4)*(IF(Besatzung!$D$11:$D$22="",Besatzung!$B$6,Besatzung!$D$11:$D$22)>=B4)),1)+(Besatzung!$F$13="x")*IFERROR(H4,0)/IFERROR(SUMPRODUCT((Besatzung!$B$11:$B$22<>"")*(Besatzung!$F$11:$F$22="x")*(IF(Besatzung!$C$11:$C$22="",Besatzung!$B$5,Besatzung!$C$11:$C$22)<=B4)*(IF(Besatzung!$D$11:$D$22="",Besatzung!$B$6,Besatzung!$D$11:$D$22)>=B4)),1))),IF(I4="Individuell",((K4="x")*((G4-IFERROR(H4,0))/IFERROR(COUNTIF(J4:U4,"x"),1)+(Besatzung!$F$13="x")*IFERROR(H4,0)/IFERROR(SUMPRODUCT((J4:U4="x")*(Besatzung!$F$11:$F$22="x")),1))),(IF(COUNTIF(J4:U4,"x")=0,IF(Besatzung!$B$13<>"",1,0),(K4="x"))*(G4-IFERROR(H4,0))/IFERROR(IF(COUNTIF(J4:U4,"x")=0,COUNTA(Besatzung!$B$11:$B$22),COUNTIF(J4:U4,"x")),1)+IF(COUNTIF(J4:U4,"x")=0,(Besatzung!$F$13="x"),(K4="x")*(Besatzung!$F$13="x"))*IFERROR(H4,0)/IFERROR(IF(COUNTIF(J4:U4,"x")=0,SUMPRODUCT((Besatzung!$B$11:$B$22<>"")*(Besatzung!$F$11:$F$22="x")),SUMPRODUCT((J4:U4="x")*(Besatzung!$F$11:$F$22="x"))),1))))),0)))) | Y4: =IF(C4="Gutschrift","",IF(G4="","",IF(Besatzung!$B$14="","",IFERROR(IF(I4="Zeitanteilig",(Besatzung!$G$14*(G4-IFERROR(H4,0))+((Besatzung!$B$14<>"")*IF(B4="",1,(IF(Besatzung!$C$14="",Besatzung!$B$5,Besatzung!$C$14)<=B4)*(IF(Besatzung!$D$14="",Besatzung!$B$6,Besatzung!$D$14)>=B4)))*(Besatzung!$F$14="x")*IFERROR(H4,0)/IFERROR(SUMPRODUCT((Besatzung!$B$11:$B$22<>"")*(Besatzung!$F$11:$F$22="x")*(IF(Besatzung!$C$11:$C$22="",Besatzung!$B$5,Besatzung!$C$11:$C$22)<=B4)*(IF(Besatzung!$D$11:$D$22="",Besatzung!$B$6,Besatzung!$D$11:$D$22)>=B4)),1)),IF(I4="An Bord",(((Besatzung!$B$14<>"")*IF(B4="",1,(IF(Besatzung!$C$14="",Besatzung!$B$5,Besatzung!$C$14)<=B4)*(IF(Besatzung!$D$14="",Besatzung!$B$6,Besatzung!$D$14)>=B4)))*((G4-IFERROR(H4,0))/IFERROR(SUMPRODUCT((Besatzung!$B$11:$B$22<>"")*(IF(Besatzung!$C$11:$C$22="",Besatzung!$B$5,Besatzung!$C$11:$C$22)<=B4)*(IF(Besatzung!$D$11:$D$22="",Besatzung!$B$6,Besatzung!$D$11:$D$22)>=B4)),1)+(Besatzung!$F$14="x")*IFERROR(H4,0)/IFERROR(SUMPRODUCT((Besatzung!$B$11:$B$22<>"")*(Besatzung!$F$11:$F$22="x")*(IF(Besatzung!$C$11:$C$22="",Besatzung!$B$5,Besatzung!$C$11:$C$22)<=B4)*(IF(Besatzung!$D$11:$D$22="",Besatzung!$B$6,Besatzung!$D$11:$D$22)>=B4)),1))),IF(I4="Individuell",((M4="x")*((G4-IFERROR(H4,0))/IFERROR(COUNTIF(J4:U4,"x"),1)+(Besatzung!$F$14="x")*IFERROR(H4,0)/IFERROR(SUMPRODUCT((J4:U4="x")*(Besatzung!$F$11:$F$22="x")),1))),(IF(COUNTIF(J4:U4,"x")=0,IF(Besatzung!$B$14<>"",1,0),(M4="x"))*(G4-IFERROR(H4,0))/IFERROR(IF(COUNTIF(J4:U4,"x")=0,COUNTA(Besatzung!$B$11:$B$22),COUNTIF(J4:U4,"x")),1)+IF(COUNTIF(J4:U4,"x")=0,(Besatzung!$F$14="x"),(M4="x")*(Besatzung!$F$14="x"))*IFERROR(H4,0)/IFERROR(IF(COUNTIF(J4:U4,"x")=0,SUMPRODUCT((Besatzung!$B$11:$B$22<>"")*(Besatzung!$F$11:$F$22="x")),SUMPRODUCT((J4:U4="x")*(Besatzung!$F$11:$F$22="x"))),1))))),0)))) | Z4: =IF(C4="Gutschrift","",IF(G4="","",IF(Besatzung!$B$13="","",IFERROR(IF(I4="Zeitanteilig",(Besatzung!$G$15*(G4-IFERROR(H4,0))+((Besatzung!$B$13<>"")*IF(B4="",1,(IF(Besatzung!$C$15="",Besatzung!$B$5,Besatzung!$C$15)<=B4)*(IF(Besatzung!$D$15="",Besatzung!$B$6,Besatzung!$D$15)>=B4)))*(Besatzung!$F$15="x")*IFERROR(H4,0)/IFERROR(SUMPRODUCT((Besatzung!$B$11:$B$22<>"")*(Besatzung!$F$11:$F$22="x")*(IF(Besatzung!$C$11:$C$22="",Besatzung!$B$5,Besatzung!$C$11:$C$22)<=B4)*(IF(Besatzung!$D$11:$D$22="",Besatzung!$B$6,Besatzung!$D$11:$D$22)>=B4)),1)),IF(I4="An Bord",(((Besatzung!$B$13<>"")*IF(B4="",1,(IF(Besatzung!$C$15="",Besatzung!$B$5,Besatzung!$C$15)<=B4)*(IF(Besatzung!$D$15="",Besatzung!$B$6,Besatzung!$D$15)>=B4)))*((G4-IFERROR(H4,0))/IFERROR(SUMPRODUCT((Besatzung!$B$11:$B$22<>"")*(IF(Besatzung!$C$11:$C$22="",Besatzung!$B$5,Besatzung!$C$11:$C$22)<=B4)*(IF(Besatzung!$D$11:$D$22="",Besatzung!$B$6,Besatzung!$D$11:$D$22)>=B4)),1)+(Besatzung!$F$15="x")*IFERROR(H4,0)/IFERROR(SUMPRODUCT((Besatzung!$B$11:$B$22<>"")*(Besatzung!$F$11:$F$22="x")*(IF(Besatzung!$C$11:$C$22="",Besatzung!$B$5,Besatzung!$C$11:$C$22)<=B4)*(IF(Besatzung!$D$11:$D$22="",Besatzung!$B$6,Besatzung!$D$11:$D$22)>=B4)),1))),IF(I4="Individuell",((N4="x")*((G4-IFERROR(H4,0))/IFERROR(COUNTIF(J4:U4,"x"),1)+(Besatzung!$F$15="x")*IFERROR(H4,0)/IFERROR(SUMPRODUCT((J4:U4="x")*(Besatzung!$F$11:$F$22="x")),1))),(IF(COUNTIF(J4:U4,"x")=0,IF(Besatzung!$B$13<>"",1,0),(N4="x"))*(G4-IFERROR(H4,0))/IFERROR(IF(COUNTIF(J4:U4,"x")=0,COUNTA(Besatzung!$B$11:$B$22),COUNTIF(J4:U4,"x")),1)+IF(COUNTIF(J4:U4,"x")=0,(Besatzung!$F$15="x"),(N4="x")*(Besatzung!$F$15="x"))*IFERROR(H4,0)/IFERROR(IF(COUNTIF(J4:U4,"x")=0,SUMPRODUCT((Besatzung!$B$11:$B$22<>"")*(Besatzung!$F$11:$F$22="x")),SUMPRODUCT((J4:U4="x")*(Besatzung!$F$11:$F$22="x"))),1))))),0)))) | AA4: =IF(C4="Gutschrift","",IF(G4="","",IF(Besatzung!$B$15="","",IFERROR(IF(I4="Zeitanteilig",(Besatzung!$G$16*(G4-IFERROR(H4,0))+((Besatzung!$B$15<>"")*IF(B4="",1,(IF(Besatzung!$C$16="",Besatzung!$B$5,Besatzung!$C$16)<=B4)*(IF(Besatzung!$D$16="",Besatzung!$B$6,Besatzung!$D$16)>=B4)))*(Besatzung!$F$16="x")*IFERROR(H4,0)/IFERROR(SUMPRODUCT((Besatzung!$B$11:$B$22<>"")*(Besatzung!$F$11:$F$22="x")*(IF(Besatzung!$C$11:$C$22="",Besatzung!$B$5,Besatzung!$C$11:$C$22)<=B4)*(IF(Besatzung!$D$11:$D$22="",Besatzung!$B$6,Besatzung!$D$11:$D$22)>=B4)),1)),IF(I4="An Bord",(((Besatzung!$B$15<>"")*IF(B4="",1,(IF(Besatzung!$C$16="",Besatzung!$B$5,Besatzung!$C$16)<=B4)*(IF(Besatzung!$D$16="",Besatzung!$B$6,Besatzung!$D$16)>=B4)))*((G4-IFERROR(H4,0))/IFERROR(SUMPRODUCT((Besatzung!$B$11:$B$22<>"")*(IF(Besatzung!$C$11:$C$22="",Besatzung!$B$5,Besatzung!$C$11:$C$22)<=B4)*(IF(Besatzung!$D$11:$D$22="",Besatzung!$B$6,Besatzung!$D$11:$D$22)>=B4)),1)+(Besatzung!$F$16="x")*IFERROR(H4,0)/IFERROR(SUMPRODUCT((Besatzung!$B$11:$B$22<>"")*(Besatzung!$F$11:$F$22="x")*(IF(Besatzung!$C$11:$C$22="",Besatzung!$B$5,Besatzung!$C$11:$C$22)<=B4)*(IF(Besatzung!$D$11:$D$22="",Besatzung!$B$6,Besatzung!$D$11:$D$22)>=B4)),1))),IF(I4="Individuell",((O4="x")*((G4-IFERROR(H4,0))/IFERROR(COUNTIF(J4:U4,"x"),1)+(Besatzung!$F$16="x")*IFERROR(H4,0)/IFERROR(SUMPRODUCT((J4:U4="x")*(Besatzung!$F$11:$F$22="x")),1))),(IF(COUNTIF(J4:U4,"x")=0,IF(Besatzung!$B$15<>"",1,0),(O4="x"))*(G4-IFERROR(H4,0))/IFERROR(IF(COUNTIF(J4:U4,"x")=0,COUNTA(Besatzung!$B$11:$B$22),COUNTIF(J4:U4,"x")),1)+IF(COUNTIF(J4:U4,"x")=0,(Besatzung!$F$16="x"),(O4="x")*(Besatzung!$F$16="x"))*IFERROR(H4,0)/IFERROR(IF(COUNTIF(J4:U4,"x")=0,SUMPRODUCT((Besatzung!$B$11:$B$22<>"")*(Besatzung!$F$11:$F$22="x")),SUMPRODUCT((J4:U4="x")*(Besatzung!$F$11:$F$22="x"))),1))))),0)))) | AB4: =IF(C4="Gutschrift","",IF(G4="","",IF(Besatzung!$B$17="","",IFERROR(IF(I4="Zeitanteilig",(Besatzung!$G$17*(G4-IFERROR(H4,0))+((Besatzung!$B$17<>"")*IF(B4="",1,(IF(Besatzung!$C$17="",Besatzung!$B$5,Besatzung!$C$17)<=B4)*(IF(Besatzung!$D$17="",Besatzung!$B$6,Besatzung!$D$17)>=B4)))*(Besatzung!$F$17="x")*IFERROR(H4,0)/IFERROR(SUMPRODUCT((Besatzung!$B$11:$B$22<>"")*(Besatzung!$F$11:$F$22="x")*(IF(Besatzung!$C$11:$C$22="",Besatzung!$B$5,Besatzung!$C$11:$C$22)<=B4)*(IF(Besatzung!$D$11:$D$22="",Besatzung!$B$6,Besatzung!$D$11:$D$22)>=B4)),1)),IF(I4="An Bord",(((Besatzung!$B$17<>"")*IF(B4="",1,(IF(Besatzung!$C$17="",Besatzung!$B$5,Besatzung!$C$17)<=B4)*(IF(Besatzung!$D$17="",Besatzung!$B$6,Besatzung!$D$17)>=B4)))*((G4-IFERROR(H4,0))/IFERROR(SUMPRODUCT((Besatzung!$B$11:$B$22<>"")*(IF(Besatzung!$C$11:$C$22="",Besatzung!$B$5,Besatzung!$C$11:$C$22)<=B4)*(IF(Besatzung!$D$11:$D$22="",Besatzung!$B$6,Besatzung!$D$11:$D$22)>=B4)),1)+(Besatzung!$F$17="x")*IFERROR(H4,0)/IFERROR(SUMPRODUCT((Besatzung!$B$11:$B$22<>"")*(Besatzung!$F$11:$F$22="x")*(IF(Besatzung!$C$11:$C$22="",Besatzung!$B$5,Besatzung!$C$11:$C$22)<=B4)*(IF(Besatzung!$D$11:$D$22="",Besatzung!$B$6,Besatzung!$D$11:$D$22)>=B4)),1))),IF(I4="Individuell",((P4="x")*((G4-IFERROR(H4,0))/IFERROR(COUNTIF(J4:U4,"x"),1)+(Besatzung!$F$17="x")*IFERROR(H4,0)/IFERROR(SUMPRODUCT((J4:U4="x")*(Besatzung!$F$11:$F$22="x")),1))),(IF(COUNTIF(J4:U4,"x")=0,IF(Besatzung!$B$17<>"",1,0),(P4="x"))*(G4-IFERROR(H4,0))/IFERROR(IF(COUNTIF(J4:U4,"x")=0,COUNTA(Besatzung!$B$11:$B$22),COUNTIF(J4:U4,"x")),1)+IF(COUNTIF(J4:U4,"x")=0,(Besatzung!$F$17="x"),(P4="x")*(Besatzung!$F$17="x"))*IFERROR(H4,0)/IFERROR(IF(COUNTIF(J4:U4,"x")=0,SUMPRODUCT((Besatzung!$B$11:$B$22<>"")*(Besatzung!$F$11:$F$22="x")),SUMPRODUCT((J4:U4="x")*(Besatzung!$F$11:$F$22="x"))),1))))),0)))) | AC4: =IF(C4="Gutschrift","",IF(G4="","",IF(Besatzung!$B$18="","",IFERROR(IF(I4="Zeitanteilig",(Besatzung!$G$18*(G4-IFERROR(H4,0))+((Besatzung!$B$18<>"")*IF(B4="",1,(IF(Besatzung!$C$18="",Besatzung!$B$5,Besatzung!$C$18)<=B4)*(IF(Besatzung!$D$18="",Besatzung!$B$6,Besatzung!$D$18)>=B4)))*(Besatzung!$F$18="x")*IFERROR(H4,0)/IFERROR(SUMPRODUCT((Besatzung!$B$11:$B$22<>"")*(Besatzung!$F$11:$F$22="x")*(IF(Besatzung!$C$11:$C$22="",Besatzung!$B$5,Besatzung!$C$11:$C$22)<=B4)*(IF(Besatzung!$D$11:$D$22="",Besatzung!$B$6,Besatzung!$D$11:$D$22)>=B4)),1)),IF(I4="An Bord",(((Besatzung!$B$18<>"")*IF(B4="",1,(IF(Besatzung!$C$18="",Besatzung!$B$5,Besatzung!$C$18)<=B4)*(IF(Besatzung!$D$18="",Besatzung!$B$6,Besatzung!$D$18)>=B4)))*((G4-IFERROR(H4,0))/IFERROR(SUMPRODUCT((Besatzung!$B$11:$B$22<>"")*(IF(Besatzung!$C$11:$C$22="",Besatzung!$B$5,Besatzung!$C$11:$C$22)<=B4)*(IF(Besatzung!$D$11:$D$22="",Besatzung!$B$6,Besatzung!$D$11:$D$22)>=B4)),1)+(Besatzung!$F$18="x")*IFERROR(H4,0)/IFERROR(SUMPRODUCT((Besatzung!$B$11:$B$22<>"")*(Besatzung!$F$11:$F$22="x")*(IF(Besatzung!$C$11:$C$22="",Besatzung!$B$5,Besatzung!$C$11:$C$22)<=B4)*(IF(Besatzung!$D$11:$D$22="",Besatzung!$B$6,Besatzung!$D$11:$D$22)>=B4)),1))),IF(I4="Individuell",((Q4="x")*((G4-IFERROR(H4,0))/IFERROR(COUNTIF(J4:U4,"x"),1)+(Besatzung!$F$18="x")*IFERROR(H4,0)/IFERROR(SUMPRODUCT((J4:U4="x")*(Besatzung!$F$11:$F$22="x")),1))),(IF(COUNTIF(J4:U4,"x")=0,IF(Besatzung!$B$18<>"",1,0),(Q4="x"))*(G4-IFERROR(H4,0))/IFERROR(IF(COUNTIF(J4:U4,"x")=0,COUNTA(Besatzung!$B$11:$B$22),COUNTIF(J4:U4,"x")),1)+IF(COUNTIF(J4:U4,"x")=0,(Besatzung!$F$18="x"),(Q4="x")*(Besatzung!$F$18="x"))*IFERROR(H4,0)/IFERROR(IF(COUNTIF(J4:U4,"x")=0,SUMPRODUCT((Besatzung!$B$11:$B$22<>"")*(Besatzung!$F$11:$F$22="x")),SUMPRODUCT((J4:U4="x")*(Besatzung!$F$11:$F$22="x"))),1))))),0)))) | AD4: =IF(C4="Gutschrift","",IF(G4="","",IF(Besatzung!$B$19="","",IFERROR(IF(I4="Zeitanteilig",(Besatzung!$G$19*(G4-IFERROR(H4,0))+((Besatzung!$B$19<>"")*IF(B4="",1,(IF(Besatzung!$C$19="",Besatzung!$B$5,Besatzung!$C$19)<=B4)*(IF(Besatzung!$D$19="",Besatzung!$B$6,Besatzung!$D$19)>=B4)))*(Besatzung!$F$19="x")*IFERROR(H4,0)/IFERROR(SUMPRODUCT((Besatzung!$B$11:$B$22<>"")*(Besatzung!$F$11:$F$22="x")*(IF(Besatzung!$C$11:$C$22="",Besatzung!$B$5,Besatzung!$C$11:$C$22)<=B4)*(IF(Besatzung!$D$11:$D$22="",Besatzung!$B$6,Besatzung!$D$11:$D$22)>=B4)),1)),IF(I4="An Bord",(((Besatzung!$B$19<>"")*IF(B4="",1,(IF(Besatzung!$C$19="",Besatzung!$B$5,Besatzung!$C$19)<=B4)*(IF(Besatzung!$D$19="",Besatzung!$B$6,Besatzung!$D$19)>=B4)))*((G4-IFERROR(H4,0))/IFERROR(SUMPRODUCT((Besatzung!$B$11:$B$22<>"")*(IF(Besatzung!$C$11:$C$22="",Besatzung!$B$5,Besatzung!$C$11:$C$22)<=B4)*(IF(Besatzung!$D$11:$D$22="",Besatzung!$B$6,Besatzung!$D$11:$D$22)>=B4)),1)+(Besatzung!$F$19="x")*IFERROR(H4,0)/IFERROR(SUMPRODUCT((Besatzung!$B$11:$B$22<>"")*(Besatzung!$F$11:$F$22="x")*(IF(Besatzung!$C$11:$C$22="",Besatzung!$B$5,Besatzung!$C$11:$C$22)<=B4)*(IF(Besatzung!$D$11:$D$22="",Besatzung!$B$6,Besatzung!$D$11:$D$22)>=B4)),1))),IF(I4="Individuell",((R4="x")*((G4-IFERROR(H4,0))/IFERROR(COUNTIF(J4:U4,"x"),1)+(Besatzung!$F$19="x")*IFERROR(H4,0)/IFERROR(SUMPRODUCT((J4:U4="x")*(Besatzung!$F$11:$F$22="x")),1))),(IF(COUNTIF(J4:U4,"x")=0,IF(Besatzung!$B$19<>"",1,0),(R4="x"))*(G4-IFERROR(H4,0))/IFERROR(IF(COUNTIF(J4:U4,"x")=0,COUNTA(Besatzung!$B$11:$B$22),COUNTIF(J4:U4,"x")),1)+IF(COUNTIF(J4:U4,"x")=0,(Besatzung!$F$19="x"),(R4="x")*(Besatzung!$F$19="x"))*IFERROR(H4,0)/IFERROR(IF(COUNTIF(J4:U4,"x")=0,SUMPRODUCT((Besatzung!$B$11:$B$22<>"")*(Besatzung!$F$11:$F$22="x")),SUMPRODUCT((J4:U4="x")*(Besatzung!$F$11:$F$22="x"))),1))))),0)))) | AE4: =IF(C4="Gutschrift","",IF(G4="","",IF(Besatzung!$B$20="","",IFERROR(IF(I4="Zeitanteilig",(Besatzung!$G$20*(G4-IFERROR(H4,0))+((Besatzung!$B$20<>"")*IF(B4="",1,(IF(Besatzung!$C$20="",Besatzung!$B$5,Besatzung!$C$20)<=B4)*(IF(Besatzung!$D$20="",Besatzung!$B$6,Besatzung!$D$20)>=B4)))*(Besatzung!$F$20="x")*IFERROR(H4,0)/IFERROR(SUMPRODUCT((Besatzung!$B$11:$B$22<>"")*(Besatzung!$F$11:$F$22="x")*(IF(Besatzung!$C$11:$C$22="",Besatzung!$B$5,Besatzung!$C$11:$C$22)<=B4)*(IF(Besatzung!$D$11:$D$22="",Besatzung!$B$6,Besatzung!$D$11:$D$22)>=B4)),1)),IF(I4="An Bord",(((Besatzung!$B$20<>"")*IF(B4="",1,(IF(Besatzung!$C$20="",Besatzung!$B$5,Besatzung!$C$20)<=B4)*(IF(Besatzung!$D$20="",Besatzung!$B$6,Besatzung!$D$20)>=B4)))*((G4-IFERROR(H4,0))/IFERROR(SUMPRODUCT((Besatzung!$B$11:$B$22<>"")*(IF(Besatzung!$C$11:$C$22="",Besatzung!$B$5,Besatzung!$C$11:$C$22)<=B4)*(IF(Besatzung!$D$11:$D$22="",Besatzung!$B$6,Besatzung!$D$11:$D$22)>=B4)),1)+(Besatzung!$F$20="x")*IFERROR(H4,0)/IFERROR(SUMPRODUCT((Besatzung!$B$11:$B$22<>"")*(Besatzung!$F$11:$F$22="x")*(IF(Besatzung!$C$11:$C$22="",Besatzung!$B$5,Besatzung!$C$11:$C$22)<=B4)*(IF(Besatzung!$D$11:$D$22="",Besatzung!$B$6,Besatzung!$D$11:$D$22)>=B4)),1))),IF(I4="Individuell",((S4="x")*((G4-IFERROR(H4,0))/IFERROR(COUNTIF(J4:U4,"x"),1)+(Besatzung!$F$20="x")*IFERROR(H4,0)/IFERROR(SUMPRODUCT((J4:U4="x")*(Besatzung!$F$11:$F$22="x")),1))),(IF(COUNTIF(J4:U4,"x")=0,IF(Besatzung!$B$20<>"",1,0),(S4="x"))*(G4-IFERROR(H4,0))/IFERROR(IF(COUNTIF(J4:U4,"x")=0,COUNTA(Besatzung!$B$11:$B$22),COUNTIF(J4:U4,"x")),1)+IF(COUNTIF(J4:U4,"x")=0,(Besatzung!$F$20="x"),(S4="x")*(Besatzung!$F$20="x"))*IFERROR(H4,0)/IFERROR(IF(COUNTIF(J4:U4,"x")=0,SUMPRODUCT((Besatzung!$B$11:$B$22<>"")*(Besatzung!$F$11:$F$22="x")),SUMPRODUCT((J4:U4="x")*(Besatzung!$F$11:$F$22="x"))),1))))),0)))) | AF4: =IF(C4="Gutschrift","",IF(G4="","",IF(Besatzung!$B$21="","",IFERROR(IF(I4="Zeitanteilig",(Besatzung!$G$21*(G4-IFERROR(H4,0))+((Besatzung!$B$21<>"")*IF(B4="",1,(IF(Besatzung!$C$21="",Besatzung!$B$5,Besatzung!$C$21)<=B4)*(IF(Besatzung!$D$21="",Besatzung!$B$6,Besatzung!$D$21)>=B4)))*(Besatzung!$F$21="x")*IFERROR(H4,0)/IFERROR(SUMPRODUCT((Besatzung!$B$11:$B$22<>"")*(Besatzung!$F$11:$F$22="x")*(IF(Besatzung!$C$11:$C$22="",Besatzung!$B$5,Besatzung!$C$11:$C$22)<=B4)*(IF(Besatzung!$D$11:$D$22="",Besatzung!$B$6,Besatzung!$D$11:$D$22)>=B4)),1)),IF(I4="An Bord",(((Besatzung!$B$21<>"")*IF(B4="",1,(IF(Besatzung!$C$21="",Besatzung!$B$5,Besatzung!$C$21)<=B4)*(IF(Besatzung!$D$21="",Besatzung!$B$6,Besatzung!$D$21)>=B4)))*((G4-IFERROR(H4,0))/IFERROR(SUMPRODUCT((Besatzung!$B$11:$B$22<>"")*(IF(Besatzung!$C$11:$C$22="",Besatzung!$B$5,Besatzung!$C$11:$C$22)<=B4)*(IF(Besatzung!$D$11:$D$22="",Besatzung!$B$6,Besatzung!$D$11:$D$22)>=B4)),1)+(Besatzung!$F$21="x")*IFERROR(H4,0)/IFERROR(SUMPRODUCT((Besatzung!$B$11:$B$22<>"")*(Besatzung!$F$11:$F$22="x")*(IF(Besatzung!$C$11:$C$22="",Besatzung!$B$5,Besatzung!$C$11:$C$22)<=B4)*(IF(Besatzung!$D$11:$D$22="",Besatzung!$B$6,Besatzung!$D$11:$D$22)>=B4)),1))),IF(I4="Individuell",((T4="x")*((G4-IFERROR(H4,0))/IFERROR(COUNTIF(J4:U4,"x"),1)+(Besatzung!$F$21="x")*IFERROR(H4,0)/IFERROR(SUMPRODUCT((J4:U4="x")*(Besatzung!$F$11:$F$22="x")),1))),(IF(COUNTIF(J4:U4,"x")=0,IF(Besatzung!$B$21<>"",1,0),(T4="x"))*(G4-IFERROR(H4,0))/IFERROR(IF(COUNTIF(J4:U4,"x")=0,COUNTA(Besatzung!$B$11:$B$22),COUNTIF(J4:U4,"x")),1)+IF(COUNTIF(J4:U4,"x")=0,(Besatzung!$F$21="x"),(T4="x")*(Besatzung!$F$21="x"))*IFERROR(H4,0)/IFERROR(IF(COUNTIF(J4:U4,"x")=0,SUMPRODUCT((Besatzung!$B$11:$B$22<>"")*(Besatzung!$F$11:$F$22="x")),SUMPRODUCT((J4:U4="x")*(Besatzung!$F$11:$F$22="x"))),1))))),0)))) | AG4: =IF(C4="Gutschrift","",IF(G4="","",IF(Besatzung!$B$22="","",IFERROR(IF(I4="Zeitanteilig",(Besatzung!$G$22*(G4-IFERROR(H4,0))+((Besatzung!$B$22<>"")*IF(B4="",1,(IF(Besatzung!$C$22="",Besatzung!$B$5,Besatzung!$C$22)<=B4)*(IF(Besatzung!$D$22="",Besatzung!$B$6,Besatzung!$D$22)>=B4)))*(Besatzung!$F$22="x")*IFERROR(H4,0)/IFERROR(SUMPRODUCT((Besatzung!$B$11:$B$22<>"")*(Besatzung!$F$11:$F$22="x")*(IF(Besatzung!$C$11:$C$22="",Besatzung!$B$5,Besatzung!$C$11:$C$22)<=B4)*(IF(Besatzung!$D$11:$D$22="",Besatzung!$B$6,Besatzung!$D$11:$D$22)>=B4)),1)),IF(I4="An Bord",(((Besatzung!$B$22<>"")*IF(B4="",1,(IF(Besatzung!$C$22="",Besatzung!$B$5,Besatzung!$C$22)<=B4)*(IF(Besatzung!$D$22="",Besatzung!$B$6,Besatzung!$D$22)>=B4)))*((G4-IFERROR(H4,0))/IFERROR(SUMPRODUCT((Besatzung!$B$11:$B$22<>"")*(IF(Besatzung!$C$11:$C$22="",Besatzung!$B$5,Besatzung!$C$11:$C$22)<=B4)*(IF(Besatzung!$D$11:$D$22="",Besatzung!$B$6,Besatzung!$D$11:$D$22)>=B4)),1)+(Besatzung!$F$22="x")*IFERROR(H4,0)/IFERROR(SUMPRODUCT((Besatzung!$B$11:$B$22<>"")*(Besatzung!$F$11:$F$22="x")*(IF(Besatzung!$C$11:$C$22="",Besatzung!$B$5,Besatzung!$C$11:$C$22)<=B4)*(IF(Besatzung!$D$11:$D$22="",Besatzung!$B$6,Besatzung!$D$11:$D$22)>=B4)),1))),IF(I4="Individuell",((U4="x")*((G4-IFERROR(H4,0))/IFERROR(COUNTIF(J4:U4,"x"),1)+(Besatzung!$F$22="x")*IFERROR(H4,0)/IFERROR(SUMPRODUCT((J4:U4="x")*(Besatzung!$F$11:$F$22="x")),1))),(IF(COUNTIF(J4:U4,"x")=0,IF(Besatzung!$B$22<>"",1,0),(U4="x"))*(G4-IFERROR(H4,0))/IFERROR(IF(COUNTIF(J4:U4,"x")=0,COUNTA(Besatzung!$B$11:$B$22),COUNTIF(J4:U4,"x")),1)+IF(COUNTIF(J4:U4,"x")=0,(Besatzung!$F$22="x"),(U4="x")*(Besatzung!$F$22="x"))*IFERROR(H4,0)/IFERROR(IF(COUNTIF(J4:U4,"x")=0,SUMPRODUCT((Besatzung!$B$11:$B$22<>"")*(Besatzung!$F$11:$F$22="x")),SUMPRODUCT((J4:U4="x")*(Besatzung!$F$11:$F$22="x"))),1))))),0))))
A5: =IF(AND(D5="",C5=""),"",2) | V5: =IF(C5="Gutschrift","",IF(G5="","",IF(Besatzung!$B$11="","",IFERROR(IF(I5="Zeitanteilig",(Besatzung!$G$11*(G5-IFERROR(H5,0))+((Besatzung!$B$11<>"")*IF(B5="",1,(IF(Besatzung!$C$11="",Besatzung!$B$5,Besatzung!$C$11)<=B5)*(IF(Besatzung!$D$11="",Besatzung!$B$6,Besatzung!$D$11)>=B5)))*(Besatzung!$F$11="x")*IFERROR(H5,0)/IFERROR(SUMPRODUCT((Besatzung!$B$11:$B$22<>"")*(Besatzung!$F$11:$F$22="x")*(IF(Besatzung!$C$11:$C$22="",Besatzung!$B$5,Besatzung!$C$11:$C$22)<=B5)*(IF(Besatzung!$D$11:$D$22="",Besatzung!$B$6,Besatzung!$D$11:$D$22)>=B5)),1)),IF(I5="An Bord",(((Besatzung!$B$11<>"")*IF(B5="",1,(IF(Besatzung!$C$11="",Besatzung!$B$5,Besatzung!$C$11)<=B5)*(IF(Besatzung!$D$11="",Besatzung!$B$6,Besatzung!$D$11)>=B5)))*((G5-IFERROR(H5,0))/IFERROR(SUMPRODUCT((Besatzung!$B$11:$B$22<>"")*(IF(Besatzung!$C$11:$C$22="",Besatzung!$B$5,Besatzung!$C$11:$C$22)<=B5)*(IF(Besatzung!$D$11:$D$22="",Besatzung!$B$6,Besatzung!$D$11:$D$22)>=B5)),1)+(Besatzung!$F$11="x")*IFERROR(H5,0)/IFERROR(SUMPRODUCT((Besatzung!$B$11:$B$22<>"")*(Besatzung!$F$11:$F$22="x")*(IF(Besatzung!$C$11:$C$22="",Besatzung!$B$5,Besatzung!$C$11:$C$22)<=B5)*(IF(Besatzung!$D$11:$D$22="",Besatzung!$B$6,Besatzung!$D$11:$D$22)>=B5)),1))),IF(I5="Individuell",((J5="x")*((G5-IFERROR(H5,0))/IFERROR(COUNTIF(J5:U5,"x"),1)+(Besatzung!$F$11="x")*IFERROR(H5,0)/IFERROR(SUMPRODUCT((J5:U5="x")*(Besatzung!$F$11:$F$22="x")),1))),(IF(COUNTIF(J5:U5,"x")=0,IF(Besatzung!$B$11<>"",1,0),(J5="x"))*(G5-IFERROR(H5,0))/IFERROR(IF(COUNTIF(J5:U5,"x")=0,COUNTA(Besatzung!$B$11:$B$22),COUNTIF(J5:U5,"x")),1)+IF(COUNTIF(J5:U5,"x")=0,(Besatzung!$F$11="x"),(J5="x")*(Besatzung!$F$11="x"))*IFERROR(H5,0)/IFERROR(IF(COUNTIF(J5:U5,"x")=0,SUMPRODUCT((Besatzung!$B$11:$B$22<>"")*(Besatzung!$F$11:$F$22="x")),SUMPRODUCT((J5:U5="x")*(Besatzung!$F$11:$F$22="x"))),1))))),0)))) | W5: =IF(C5="Gutschrift","",IF(G5="","",IF(Besatzung!$B$12="","",IFERROR(IF(I5="Zeitanteilig",(Besatzung!$G$12*(G5-IFERROR(H5,0))+((Besatzung!$B$12<>"")*IF(B5="",1,(IF(Besatzung!$C$12="",Besatzung!$B$5,Besatzung!$C$12)<=B5)*(IF(Besatzung!$D$12="",Besatzung!$B$6,Besatzung!$D$12)>=B5)))*(Besatzung!$F$12="x")*IFERROR(H5,0)/IFERROR(SUMPRODUCT((Besatzung!$B$11:$B$22<>"")*(Besatzung!$F$11:$F$22="x")*(IF(Besatzung!$C$11:$C$22="",Besatzung!$B$5,Besatzung!$C$11:$C$22)<=B5)*(IF(Besatzung!$D$11:$D$22="",Besatzung!$B$6,Besatzung!$D$11:$D$22)>=B5)),1)),IF(I5="An Bord",(((Besatzung!$B$12<>"")*IF(B5="",1,(IF(Besatzung!$C$12="",Besatzung!$B$5,Besatzung!$C$12)<=B5)*(IF(Besatzung!$D$12="",Besatzung!$B$6,Besatzung!$D$12)>=B5)))*((G5-IFERROR(H5,0))/IFERROR(SUMPRODUCT((Besatzung!$B$11:$B$22<>"")*(IF(Besatzung!$C$11:$C$22="",Besatzung!$B$5,Besatzung!$C$11:$C$22)<=B5)*(IF(Besatzung!$D$11:$D$22="",Besatzung!$B$6,Besatzung!$D$11:$D$22)>=B5)),1)+(Besatzung!$F$12="x")*IFERROR(H5,0)/IFERROR(SUMPRODUCT((Besatzung!$B$11:$B$22<>"")*(Besatzung!$F$11:$F$22="x")*(IF(Besatzung!$C$11:$C$22="",Besatzung!$B$5,Besatzung!$C$11:$C$22)<=B5)*(IF(Besatzung!$D$11:$D$22="",Besatzung!$B$6,Besatzung!$D$11:$D$22)>=B5)),1))),IF(I5="Individuell",((K5="x")*((G5-IFERROR(H5,0))/IFERROR(COUNTIF(J5:U5,"x"),1)+(Besatzung!$F$12="x")*IFERROR(H5,0)/IFERROR(SUMPRODUCT((J5:U5="x")*(Besatzung!$F$11:$F$22="x")),1))),(IF(COUNTIF(J5:U5,"x")=0,IF(Besatzung!$B$12<>"",1,0),(K5="x"))*(G5-IFERROR(H5,0))/IFERROR(IF(COUNTIF(J5:U5,"x")=0,COUNTA(Besatzung!$B$11:$B$22),COUNTIF(J5:U5,"x")),1)+IF(COUNTIF(J5:U5,"x")=0,(Besatzung!$F$12="x"),(K5="x")*(Besatzung!$F$12="x"))*IFERROR(H5,0)/IFERROR(IF(COUNTIF(J5:U5,"x")=0,SUMPRODUCT((Besatzung!$B$11:$B$22<>"")*(Besatzung!$F$11:$F$22="x")),SUMPRODUCT((J5:U5="x")*(Besatzung!$F$11:$F$22="x"))),1))))),0)))) | X5: =IF(C5="Gutschrift","",IF(G5="","",IF(Besatzung!$B$13="","",IFERROR(IF(I5="Zeitanteilig",(Besatzung!$G$13*(G5-IFERROR(H5,0))+((Besatzung!$B$13<>"")*IF(B5="",1,(IF(Besatzung!$C$13="",Besatzung!$B$5,Besatzung!$C$13)<=B5)*(IF(Besatzung!$D$13="",Besatzung!$B$6,Besatzung!$D$13)>=B5)))*(Besatzung!$F$13="x")*IFERROR(H5,0)/IFERROR(SUMPRODUCT((Besatzung!$B$11:$B$22<>"")*(Besatzung!$F$11:$F$22="x")*(IF(Besatzung!$C$11:$C$22="",Besatzung!$B$5,Besatzung!$C$11:$C$22)<=B5)*(IF(Besatzung!$D$11:$D$22="",Besatzung!$B$6,Besatzung!$D$11:$D$22)>=B5)),1)),IF(I5="An Bord",(((Besatzung!$B$13<>"")*IF(B5="",1,(IF(Besatzung!$C$13="",Besatzung!$B$5,Besatzung!$C$13)<=B5)*(IF(Besatzung!$D$13="",Besatzung!$B$6,Besatzung!$D$13)>=B5)))*((G5-IFERROR(H5,0))/IFERROR(SUMPRODUCT((Besatzung!$B$11:$B$22<>"")*(IF(Besatzung!$C$11:$C$22="",Besatzung!$B$5,Besatzung!$C$11:$C$22)<=B5)*(IF(Besatzung!$D$11:$D$22="",Besatzung!$B$6,Besatzung!$D$11:$D$22)>=B5)),1)+(Besatzung!$F$13="x")*IFERROR(H5,0)/IFERROR(SUMPRODUCT((Besatzung!$B$11:$B$22<>"")*(Besatzung!$F$11:$F$22="x")*(IF(Besatzung!$C$11:$C$22="",Besatzung!$B$5,Besatzung!$C$11:$C$22)<=B5)*(IF(Besatzung!$D$11:$D$22="",Besatzung!$B$6,Besatzung!$D$11:$D$22)>=B5)),1))),IF(I5="Individuell",((K5="x")*((G5-IFERROR(H5,0))/IFERROR(COUNTIF(J5:U5,"x"),1)+(Besatzung!$F$13="x")*IFERROR(H5,0)/IFERROR(SUMPRODUCT((J5:U5="x")*(Besatzung!$F$11:$F$22="x")),1))),(IF(COUNTIF(J5:U5,"x")=0,IF(Besatzung!$B$13<>"",1,0),(K5="x"))*(G5-IFERROR(H5,0))/IFERROR(IF(COUNTIF(J5:U5,"x")=0,COUNTA(Besatzung!$B$11:$B$22),COUNTIF(J5:U5,"x")),1)+IF(COUNTIF(J5:U5,"x")=0,(Besatzung!$F$13="x"),(K5="x")*(Besatzung!$F$13="x"))*IFERROR(H5,0)/IFERROR(IF(COUNTIF(J5:U5,"x")=0,SUMPRODUCT((Besatzung!$B$11:$B$22<>"")*(Besatzung!$F$11:$F$22="x")),SUMPRODUCT((J5:U5="x")*(Besatzung!$F$11:$F$22="x"))),1))))),0)))) | Y5: =IF(C5="Gutschrift","",IF(G5="","",IF(Besatzung!$B$14="","",IFERROR(IF(I5="Zeitanteilig",(Besatzung!$G$14*(G5-IFERROR(H5,0))+((Besatzung!$B$14<>"")*IF(B5="",1,(IF(Besatzung!$C$14="",Besatzung!$B$5,Besatzung!$C$14)<=B5)*(IF(Besatzung!$D$14="",Besatzung!$B$6,Besatzung!$D$14)>=B5)))*(Besatzung!$F$14="x")*IFERROR(H5,0)/IFERROR(SUMPRODUCT((Besatzung!$B$11:$B$22<>"")*(Besatzung!$F$11:$F$22="x")*(IF(Besatzung!$C$11:$C$22="",Besatzung!$B$5,Besatzung!$C$11:$C$22)<=B5)*(IF(Besatzung!$D$11:$D$22="",Besatzung!$B$6,Besatzung!$D$11:$D$22)>=B5)),1)),IF(I5="An Bord",(((Besatzung!$B$14<>"")*IF(B5="",1,(IF(Besatzung!$C$14="",Besatzung!$B$5,Besatzung!$C$14)<=B5)*(IF(Besatzung!$D$14="",Besatzung!$B$6,Besatzung!$D$14)>=B5)))*((G5-IFERROR(H5,0))/IFERROR(SUMPRODUCT((Besatzung!$B$11:$B$22<>"")*(IF(Besatzung!$C$11:$C$22="",Besatzung!$B$5,Besatzung!$C$11:$C$22)<=B5)*(IF(Besatzung!$D$11:$D$22="",Besatzung!$B$6,Besatzung!$D$11:$D$22)>=B5)),1)+(Besatzung!$F$14="x")*IFERROR(H5,0)/IFERROR(SUMPRODUCT((Besatzung!$B$11:$B$22<>"")*(Besatzung!$F$11:$F$22="x")*(IF(Besatzung!$C$11:$C$22="",Besatzung!$B$5,Besatzung!$C$11:$C$22)<=B5)*(IF(Besatzung!$D$11:$D$22="",Besatzung!$B$6,Besatzung!$D$11:$D$22)>=B5)),1))),IF(I5="Individuell",((M5="x")*((G5-IFERROR(H5,0))/IFERROR(COUNTIF(J5:U5,"x"),1)+(Besatzung!$F$14="x")*IFERROR(H5,0)/IFERROR(SUMPRODUCT((J5:U5="x")*(Besatzung!$F$11:$F$22="x")),1))),(IF(COUNTIF(J5:U5,"x")=0,IF(Besatzung!$B$14<>"",1,0),(M5="x"))*(G5-IFERROR(H5,0))/IFERROR(IF(COUNTIF(J5:U5,"x")=0,COUNTA(Besatzung!$B$11:$B$22),COUNTIF(J5:U5,"x")),1)+IF(COUNTIF(J5:U5,"x")=0,(Besatzung!$F$14="x"),(M5="x")*(Besatzung!$F$14="x"))*IFERROR(H5,0)/IFERROR(IF(COUNTIF(J5:U5,"x")=0,SUMPRODUCT((Besatzung!$B$11:$B$22<>"")*(Besatzung!$F$11:$F$22="x")),SUMPRODUCT((J5:U5="x")*(Besatzung!$F$11:$F$22="x"))),1))))),0)))) | Z5: =IF(C5="Gutschrift","",IF(G5="","",IF(Besatzung!$B$13="","",IFERROR(IF(I5="Zeitanteilig",(Besatzung!$G$15*(G5-IFERROR(H5,0))+((Besatzung!$B$13<>"")*IF(B5="",1,(IF(Besatzung!$C$15="",Besatzung!$B$5,Besatzung!$C$15)<=B5)*(IF(Besatzung!$D$15="",Besatzung!$B$6,Besatzung!$D$15)>=B5)))*(Besatzung!$F$15="x")*IFERROR(H5,0)/IFERROR(SUMPRODUCT((Besatzung!$B$11:$B$22<>"")*(Besatzung!$F$11:$F$22="x")*(IF(Besatzung!$C$11:$C$22="",Besatzung!$B$5,Besatzung!$C$11:$C$22)<=B5)*(IF(Besatzung!$D$11:$D$22="",Besatzung!$B$6,Besatzung!$D$11:$D$22)>=B5)),1)),IF(I5="An Bord",(((Besatzung!$B$13<>"")*IF(B5="",1,(IF(Besatzung!$C$15="",Besatzung!$B$5,Besatzung!$C$15)<=B5)*(IF(Besatzung!$D$15="",Besatzung!$B$6,Besatzung!$D$15)>=B5)))*((G5-IFERROR(H5,0))/IFERROR(SUMPRODUCT((Besatzung!$B$11:$B$22<>"")*(IF(Besatzung!$C$11:$C$22="",Besatzung!$B$5,Besatzung!$C$11:$C$22)<=B5)*(IF(Besatzung!$D$11:$D$22="",Besatzung!$B$6,Besatzung!$D$11:$D$22)>=B5)),1)+(Besatzung!$F$15="x")*IFERROR(H5,0)/IFERROR(SUMPRODUCT((Besatzung!$B$11:$B$22<>"")*(Besatzung!$F$11:$F$22="x")*(IF(Besatzung!$C$11:$C$22="",Besatzung!$B$5,Besatzung!$C$11:$C$22)<=B5)*(IF(Besatzung!$D$11:$D$22="",Besatzung!$B$6,Besatzung!$D$11:$D$22)>=B5)),1))),IF(I5="Individuell",((N5="x")*((G5-IFERROR(H5,0))/IFERROR(COUNTIF(J5:U5,"x"),1)+(Besatzung!$F$15="x")*IFERROR(H5,0)/IFERROR(SUMPRODUCT((J5:U5="x")*(Besatzung!$F$11:$F$22="x")),1))),(IF(COUNTIF(J5:U5,"x")=0,IF(Besatzung!$B$13<>"",1,0),(N5="x"))*(G5-IFERROR(H5,0))/IFERROR(IF(COUNTIF(J5:U5,"x")=0,COUNTA(Besatzung!$B$11:$B$22),COUNTIF(J5:U5,"x")),1)+IF(COUNTIF(J5:U5,"x")=0,(Besatzung!$F$15="x"),(N5="x")*(Besatzung!$F$15="x"))*IFERROR(H5,0)/IFERROR(IF(COUNTIF(J5:U5,"x")=0,SUMPRODUCT((Besatzung!$B$11:$B$22<>"")*(Besatzung!$F$11:$F$22="x")),SUMPRODUCT((J5:U5="x")*(Besatzung!$F$11:$F$22="x"))),1))))),0)))) | AA5: =IF(C5="Gutschrift","",IF(G5="","",IF(Besatzung!$B$15="","",IFERROR(IF(I5="Zeitanteilig",(Besatzung!$G$16*(G5-IFERROR(H5,0))+((Besatzung!$B$15<>"")*IF(B5="",1,(IF(Besatzung!$C$16="",Besatzung!$B$5,Besatzung!$C$16)<=B5)*(IF(Besatzung!$D$16="",Besatzung!$B$6,Besatzung!$D$16)>=B5)))*(Besatzung!$F$16="x")*IFERROR(H5,0)/IFERROR(SUMPRODUCT((Besatzung!$B$11:$B$22<>"")*(Besatzung!$F$11:$F$22="x")*(IF(Besatzung!$C$11:$C$22="",Besatzung!$B$5,Besatzung!$C$11:$C$22)<=B5)*(IF(Besatzung!$D$11:$D$22="",Besatzung!$B$6,Besatzung!$D$11:$D$22)>=B5)),1)),IF(I5="An Bord",(((Besatzung!$B$15<>"")*IF(B5="",1,(IF(Besatzung!$C$16="",Besatzung!$B$5,Besatzung!$C$16)<=B5)*(IF(Besatzung!$D$16="",Besatzung!$B$6,Besatzung!$D$16)>=B5)))*((G5-IFERROR(H5,0))/IFERROR(SUMPRODUCT((Besatzung!$B$11:$B$22<>"")*(IF(Besatzung!$C$11:$C$22="",Besatzung!$B$5,Besatzung!$C$11:$C$22)<=B5)*(IF(Besatzung!$D$11:$D$22="",Besatzung!$B$6,Besatzung!$D$11:$D$22)>=B5)),1)+(Besatzung!$F$16="x")*IFERROR(H5,0)/IFERROR(SUMPRODUCT((Besatzung!$B$11:$B$22<>"")*(Besatzung!$F$11:$F$22="x")*(IF(Besatzung!$C$11:$C$22="",Besatzung!$B$5,Besatzung!$C$11:$C$22)<=B5)*(IF(Besatzung!$D$11:$D$22="",Besatzung!$B$6,Besatzung!$D$11:$D$22)>=B5)),1))),IF(I5="Individuell",((O5="x")*((G5-IFERROR(H5,0))/IFERROR(COUNTIF(J5:U5,"x"),1)+(Besatzung!$F$16="x")*IFERROR(H5,0)/IFERROR(SUMPRODUCT((J5:U5="x")*(Besatzung!$F$11:$F$22="x")),1))),(IF(COUNTIF(J5:U5,"x")=0,IF(Besatzung!$B$15<>"",1,0),(O5="x"))*(G5-IFERROR(H5,0))/IFERROR(IF(COUNTIF(J5:U5,"x")=0,COUNTA(Besatzung!$B$11:$B$22),COUNTIF(J5:U5,"x")),1)+IF(COUNTIF(J5:U5,"x")=0,(Besatzung!$F$16="x"),(O5="x")*(Besatzung!$F$16="x"))*IFERROR(H5,0)/IFERROR(IF(COUNTIF(J5:U5,"x")=0,SUMPRODUCT((Besatzung!$B$11:$B$22<>"")*(Besatzung!$F$11:$F$22="x")),SUMPRODUCT((J5:U5="x")*(Besatzung!$F$11:$F$22="x"))),1))))),0)))) | AB5: =IF(C5="Gutschrift","",IF(G5="","",IF(Besatzung!$B$17="","",IFERROR(IF(I5="Zeitanteilig",(Besatzung!$G$17*(G5-IFERROR(H5,0))+((Besatzung!$B$17<>"")*IF(B5="",1,(IF(Besatzung!$C$17="",Besatzung!$B$5,Besatzung!$C$17)<=B5)*(IF(Besatzung!$D$17="",Besatzung!$B$6,Besatzung!$D$17)>=B5)))*(Besatzung!$F$17="x")*IFERROR(H5,0)/IFERROR(SUMPRODUCT((Besatzung!$B$11:$B$22<>"")*(Besatzung!$F$11:$F$22="x")*(IF(Besatzung!$C$11:$C$22="",Besatzung!$B$5,Besatzung!$C$11:$C$22)<=B5)*(IF(Besatzung!$D$11:$D$22="",Besatzung!$B$6,Besatzung!$D$11:$D$22)>=B5)),1)),IF(I5="An Bord",(((Besatzung!$B$17<>"")*IF(B5="",1,(IF(Besatzung!$C$17="",Besatzung!$B$5,Besatzung!$C$17)<=B5)*(IF(Besatzung!$D$17="",Besatzung!$B$6,Besatzung!$D$17)>=B5)))*((G5-IFERROR(H5,0))/IFERROR(SUMPRODUCT((Besatzung!$B$11:$B$22<>"")*(IF(Besatzung!$C$11:$C$22="",Besatzung!$B$5,Besatzung!$C$11:$C$22)<=B5)*(IF(Besatzung!$D$11:$D$22="",Besatzung!$B$6,Besatzung!$D$11:$D$22)>=B5)),1)+(Besatzung!$F$17="x")*IFERROR(H5,0)/IFERROR(SUMPRODUCT((Besatzung!$B$11:$B$22<>"")*(Besatzung!$F$11:$F$22="x")*(IF(Besatzung!$C$11:$C$22="",Besatzung!$B$5,Besatzung!$C$11:$C$22)<=B5)*(IF(Besatzung!$D$11:$D$22="",Besatzung!$B$6,Besatzung!$D$11:$D$22)>=B5)),1))),IF(I5="Individuell",((P5="x")*((G5-IFERROR(H5,0))/IFERROR(COUNTIF(J5:U5,"x"),1)+(Besatzung!$F$17="x")*IFERROR(H5,0)/IFERROR(SUMPRODUCT((J5:U5="x")*(Besatzung!$F$11:$F$22="x")),1))),(IF(COUNTIF(J5:U5,"x")=0,IF(Besatzung!$B$17<>"",1,0),(P5="x"))*(G5-IFERROR(H5,0))/IFERROR(IF(COUNTIF(J5:U5,"x")=0,COUNTA(Besatzung!$B$11:$B$22),COUNTIF(J5:U5,"x")),1)+IF(COUNTIF(J5:U5,"x")=0,(Besatzung!$F$17="x"),(P5="x")*(Besatzung!$F$17="x"))*IFERROR(H5,0)/IFERROR(IF(COUNTIF(J5:U5,"x")=0,SUMPRODUCT((Besatzung!$B$11:$B$22<>"")*(Besatzung!$F$11:$F$22="x")),SUMPRODUCT((J5:U5="x")*(Besatzung!$F$11:$F$22="x"))),1))))),0)))) | AC5: =IF(C5="Gutschrift","",IF(G5="","",IF(Besatzung!$B$18="","",IFERROR(IF(I5="Zeitanteilig",(Besatzung!$G$18*(G5-IFERROR(H5,0))+((Besatzung!$B$18<>"")*IF(B5="",1,(IF(Besatzung!$C$18="",Besatzung!$B$5,Besatzung!$C$18)<=B5)*(IF(Besatzung!$D$18="",Besatzung!$B$6,Besatzung!$D$18)>=B5)))*(Besatzung!$F$18="x")*IFERROR(H5,0)/IFERROR(SUMPRODUCT((Besatzung!$B$11:$B$22<>"")*(Besatzung!$F$11:$F$22="x")*(IF(Besatzung!$C$11:$C$22="",Besatzung!$B$5,Besatzung!$C$11:$C$22)<=B5)*(IF(Besatzung!$D$11:$D$22="",Besatzung!$B$6,Besatzung!$D$11:$D$22)>=B5)),1)),IF(I5="An Bord",(((Besatzung!$B$18<>"")*IF(B5="",1,(IF(Besatzung!$C$18="",Besatzung!$B$5,Besatzung!$C$18)<=B5)*(IF(Besatzung!$D$18="",Besatzung!$B$6,Besatzung!$D$18)>=B5)))*((G5-IFERROR(H5,0))/IFERROR(SUMPRODUCT((Besatzung!$B$11:$B$22<>"")*(IF(Besatzung!$C$11:$C$22="",Besatzung!$B$5,Besatzung!$C$11:$C$22)<=B5)*(IF(Besatzung!$D$11:$D$22="",Besatzung!$B$6,Besatzung!$D$11:$D$22)>=B5)),1)+(Besatzung!$F$18="x")*IFERROR(H5,0)/IFERROR(SUMPRODUCT((Besatzung!$B$11:$B$22<>"")*(Besatzung!$F$11:$F$22="x")*(IF(Besatzung!$C$11:$C$22="",Besatzung!$B$5,Besatzung!$C$11:$C$22)<=B5)*(IF(Besatzung!$D$11:$D$22="",Besatzung!$B$6,Besatzung!$D$11:$D$22)>=B5)),1))),IF(I5="Individuell",((Q5="x")*((G5-IFERROR(H5,0))/IFERROR(COUNTIF(J5:U5,"x"),1)+(Besatzung!$F$18="x")*IFERROR(H5,0)/IFERROR(SUMPRODUCT((J5:U5="x")*(Besatzung!$F$11:$F$22="x")),1))),(IF(COUNTIF(J5:U5,"x")=0,IF(Besatzung!$B$18<>"",1,0),(Q5="x"))*(G5-IFERROR(H5,0))/IFERROR(IF(COUNTIF(J5:U5,"x")=0,COUNTA(Besatzung!$B$11:$B$22),COUNTIF(J5:U5,"x")),1)+IF(COUNTIF(J5:U5,"x")=0,(Besatzung!$F$18="x"),(Q5="x")*(Besatzung!$F$18="x"))*IFERROR(H5,0)/IFERROR(IF(COUNTIF(J5:U5,"x")=0,SUMPRODUCT((Besatzung!$B$11:$B$22<>"")*(Besatzung!$F$11:$F$22="x")),SUMPRODUCT((J5:U5="x")*(Besatzung!$F$11:$F$22="x"))),1))))),0)))) | AD5: =IF(C5="Gutschrift","",IF(G5="","",IF(Besatzung!$B$19="","",IFERROR(IF(I5="Zeitanteilig",(Besatzung!$G$19*(G5-IFERROR(H5,0))+((Besatzung!$B$19<>"")*IF(B5="",1,(IF(Besatzung!$C$19="",Besatzung!$B$5,Besatzung!$C$19)<=B5)*(IF(Besatzung!$D$19="",Besatzung!$B$6,Besatzung!$D$19)>=B5)))*(Besatzung!$F$19="x")*IFERROR(H5,0)/IFERROR(SUMPRODUCT((Besatzung!$B$11:$B$22<>"")*(Besatzung!$F$11:$F$22="x")*(IF(Besatzung!$C$11:$C$22="",Besatzung!$B$5,Besatzung!$C$11:$C$22)<=B5)*(IF(Besatzung!$D$11:$D$22="",Besatzung!$B$6,Besatzung!$D$11:$D$22)>=B5)),1)),IF(I5="An Bord",(((Besatzung!$B$19<>"")*IF(B5="",1,(IF(Besatzung!$C$19="",Besatzung!$B$5,Besatzung!$C$19)<=B5)*(IF(Besatzung!$D$19="",Besatzung!$B$6,Besatzung!$D$19)>=B5)))*((G5-IFERROR(H5,0))/IFERROR(SUMPRODUCT((Besatzung!$B$11:$B$22<>"")*(IF(Besatzung!$C$11:$C$22="",Besatzung!$B$5,Besatzung!$C$11:$C$22)<=B5)*(IF(Besatzung!$D$11:$D$22="",Besatzung!$B$6,Besatzung!$D$11:$D$22)>=B5)),1)+(Besatzung!$F$19="x")*IFERROR(H5,0)/IFERROR(SUMPRODUCT((Besatzung!$B$11:$B$22<>"")*(Besatzung!$F$11:$F$22="x")*(IF(Besatzung!$C$11:$C$22="",Besatzung!$B$5,Besatzung!$C$11:$C$22)<=B5)*(IF(Besatzung!$D$11:$D$22="",Besatzung!$B$6,Besatzung!$D$11:$D$22)>=B5)),1))),IF(I5="Individuell",((R5="x")*((G5-IFERROR(H5,0))/IFERROR(COUNTIF(J5:U5,"x"),1)+(Besatzung!$F$19="x")*IFERROR(H5,0)/IFERROR(SUMPRODUCT((J5:U5="x")*(Besatzung!$F$11:$F$22="x")),1))),(IF(COUNTIF(J5:U5,"x")=0,IF(Besatzung!$B$19<>"",1,0),(R5="x"))*(G5-IFERROR(H5,0))/IFERROR(IF(COUNTIF(J5:U5,"x")=0,COUNTA(Besatzung!$B$11:$B$22),COUNTIF(J5:U5,"x")),1)+IF(COUNTIF(J5:U5,"x")=0,(Besatzung!$F$19="x"),(R5="x")*(Besatzung!$F$19="x"))*IFERROR(H5,0)/IFERROR(IF(COUNTIF(J5:U5,"x")=0,SUMPRODUCT((Besatzung!$B$11:$B$22<>"")*(Besatzung!$F$11:$F$22="x")),SUMPRODUCT((J5:U5="x")*(Besatzung!$F$11:$F$22="x"))),1))))),0)))) | AE5: =IF(C5="Gutschrift","",IF(G5="","",IF(Besatzung!$B$20="","",IFERROR(IF(I5="Zeitanteilig",(Besatzung!$G$20*(G5-IFERROR(H5,0))+((Besatzung!$B$20<>"")*IF(B5="",1,(IF(Besatzung!$C$20="",Besatzung!$B$5,Besatzung!$C$20)<=B5)*(IF(Besatzung!$D$20="",Besatzung!$B$6,Besatzung!$D$20)>=B5)))*(Besatzung!$F$20="x")*IFERROR(H5,0)/IFERROR(SUMPRODUCT((Besatzung!$B$11:$B$22<>"")*(Besatzung!$F$11:$F$22="x")*(IF(Besatzung!$C$11:$C$22="",Besatzung!$B$5,Besatzung!$C$11:$C$22)<=B5)*(IF(Besatzung!$D$11:$D$22="",Besatzung!$B$6,Besatzung!$D$11:$D$22)>=B5)),1)),IF(I5="An Bord",(((Besatzung!$B$20<>"")*IF(B5="",1,(IF(Besatzung!$C$20="",Besatzung!$B$5,Besatzung!$C$20)<=B5)*(IF(Besatzung!$D$20="",Besatzung!$B$6,Besatzung!$D$20)>=B5)))*((G5-IFERROR(H5,0))/IFERROR(SUMPRODUCT((Besatzung!$B$11:$B$22<>"")*(IF(Besatzung!$C$11:$C$22="",Besatzung!$B$5,Besatzung!$C$11:$C$22)<=B5)*(IF(Besatzung!$D$11:$D$22="",Besatzung!$B$6,Besatzung!$D$11:$D$22)>=B5)),1)+(Besatzung!$F$20="x")*IFERROR(H5,0)/IFERROR(SUMPRODUCT((Besatzung!$B$11:$B$22<>"")*(Besatzung!$F$11:$F$22="x")*(IF(Besatzung!$C$11:$C$22="",Besatzung!$B$5,Besatzung!$C$11:$C$22)<=B5)*(IF(Besatzung!$D$11:$D$22="",Besatzung!$B$6,Besatzung!$D$11:$D$22)>=B5)),1))),IF(I5="Individuell",((S5="x")*((G5-IFERROR(H5,0))/IFERROR(COUNTIF(J5:U5,"x"),1)+(Besatzung!$F$20="x")*IFERROR(H5,0)/IFERROR(SUMPRODUCT((J5:U5="x")*(Besatzung!$F$11:$F$22="x")),1))),(IF(COUNTIF(J5:U5,"x")=0,IF(Besatzung!$B$20<>"",1,0),(S5="x"))*(G5-IFERROR(H5,0))/IFERROR(IF(COUNTIF(J5:U5,"x")=0,COUNTA(Besatzung!$B$11:$B$22),COUNTIF(J5:U5,"x")),1)+IF(COUNTIF(J5:U5,"x")=0,(Besatzung!$F$20="x"),(S5="x")*(Besatzung!$F$20="x"))*IFERROR(H5,0)/IFERROR(IF(COUNTIF(J5:U5,"x")=0,SUMPRODUCT((Besatzung!$B$11:$B$22<>"")*(Besatzung!$F$11:$F$22="x")),SUMPRODUCT((J5:U5="x")*(Besatzung!$F$11:$F$22="x"))),1))))),0)))) | AF5: =IF(C5="Gutschrift","",IF(G5="","",IF(Besatzung!$B$21="","",IFERROR(IF(I5="Zeitanteilig",(Besatzung!$G$21*(G5-IFERROR(H5,0))+((Besatzung!$B$21<>"")*IF(B5="",1,(IF(Besatzung!$C$21="",Besatzung!$B$5,Besatzung!$C$21)<=B5)*(IF(Besatzung!$D$21="",Besatzung!$B$6,Besatzung!$D$21)>=B5)))*(Besatzung!$F$21="x")*IFERROR(H5,0)/IFERROR(SUMPRODUCT((Besatzung!$B$11:$B$22<>"")*(Besatzung!$F$11:$F$22="x")*(IF(Besatzung!$C$11:$C$22="",Besatzung!$B$5,Besatzung!$C$11:$C$22)<=B5)*(IF(Besatzung!$D$11:$D$22="",Besatzung!$B$6,Besatzung!$D$11:$D$22)>=B5)),1)),IF(I5="An Bord",(((Besatzung!$B$21<>"")*IF(B5="",1,(IF(Besatzung!$C$21="",Besatzung!$B$5,Besatzung!$C$21)<=B5)*(IF(Besatzung!$D$21="",Besatzung!$B$6,Besatzung!$D$21)>=B5)))*((G5-IFERROR(H5,0))/IFERROR(SUMPRODUCT((Besatzung!$B$11:$B$22<>"")*(IF(Besatzung!$C$11:$C$22="",Besatzung!$B$5,Besatzung!$C$11:$C$22)<=B5)*(IF(Besatzung!$D$11:$D$22="",Besatzung!$B$6,Besatzung!$D$11:$D$22)>=B5)),1)+(Besatzung!$F$21="x")*IFERROR(H5,0)/IFERROR(SUMPRODUCT((Besatzung!$B$11:$B$22<>"")*(Besatzung!$F$11:$F$22="x")*(IF(Besatzung!$C$11:$C$22="",Besatzung!$B$5,Besatzung!$C$11:$C$22)<=B5)*(IF(Besatzung!$D$11:$D$22="",Besatzung!$B$6,Besatzung!$D$11:$D$22)>=B5)),1))),IF(I5="Individuell",((T5="x")*((G5-IFERROR(H5,0))/IFERROR(COUNTIF(J5:U5,"x"),1)+(Besatzung!$F$21="x")*IFERROR(H5,0)/IFERROR(SUMPRODUCT((J5:U5="x")*(Besatzung!$F$11:$F$22="x")),1))),(IF(COUNTIF(J5:U5,"x")=0,IF(Besatzung!$B$21<>"",1,0),(T5="x"))*(G5-IFERROR(H5,0))/IFERROR(IF(COUNTIF(J5:U5,"x")=0,COUNTA(Besatzung!$B$11:$B$22),COUNTIF(J5:U5,"x")),1)+IF(COUNTIF(J5:U5,"x")=0,(Besatzung!$F$21="x"),(T5="x")*(Besatzung!$F$21="x"))*IFERROR(H5,0)/IFERROR(IF(COUNTIF(J5:U5,"x")=0,SUMPRODUCT((Besatzung!$B$11:$B$22<>"")*(Besatzung!$F$11:$F$22="x")),SUMPRODUCT((J5:U5="x")*(Besatzung!$F$11:$F$22="x"))),1))))),0)))) | AG5: =IF(C5="Gutschrift","",IF(G5="","",IF(Besatzung!$B$22="","",IFERROR(IF(I5="Zeitanteilig",(Besatzung!$G$22*(G5-IFERROR(H5,0))+((Besatzung!$B$22<>"")*IF(B5="",1,(IF(Besatzung!$C$22="",Besatzung!$B$5,Besatzung!$C$22)<=B5)*(IF(Besatzung!$D$22="",Besatzung!$B$6,Besatzung!$D$22)>=B5)))*(Besatzung!$F$22="x")*IFERROR(H5,0)/IFERROR(SUMPRODUCT((Besatzung!$B$11:$B$22<>"")*(Besatzung!$F$11:$F$22="x")*(IF(Besatzung!$C$11:$C$22="",Besatzung!$B$5,Besatzung!$C$11:$C$22)<=B5)*(IF(Besatzung!$D$11:$D$22="",Besatzung!$B$6,Besatzung!$D$11:$D$22)>=B5)),1)),IF(I5="An Bord",(((Besatzung!$B$22<>"")*IF(B5="",1,(IF(Besatzung!$C$22="",Besatzung!$B$5,Besatzung!$C$22)<=B5)*(IF(Besatzung!$D$22="",Besatzung!$B$6,Besatzung!$D$22)>=B5)))*((G5-IFERROR(H5,0))/IFERROR(SUMPRODUCT((Besatzung!$B$11:$B$22<>"")*(IF(Besatzung!$C$11:$C$22="",Besatzung!$B$5,Besatzung!$C$11:$C$22)<=B5)*(IF(Besatzung!$D$11:$D$22="",Besatzung!$B$6,Besatzung!$D$11:$D$22)>=B5)),1)+(Besatzung!$F$22="x")*IFERROR(H5,0)/IFERROR(SUMPRODUCT((Besatzung!$B$11:$B$22<>"")*(Besatzung!$F$11:$F$22="x")*(IF(Besatzung!$C$11:$C$22="",Besatzung!$B$5,Besatzung!$C$11:$C$22)<=B5)*(IF(Besatzung!$D$11:$D$22="",Besatzung!$B$6,Besatzung!$D$11:$D$22)>=B5)),1))),IF(I5="Individuell",((U5="x")*((G5-IFERROR(H5,0))/IFERROR(COUNTIF(J5:U5,"x"),1)+(Besatzung!$F$22="x")*IFERROR(H5,0)/IFERROR(SUMPRODUCT((J5:U5="x")*(Besatzung!$F$11:$F$22="x")),1))),(IF(COUNTIF(J5:U5,"x")=0,IF(Besatzung!$B$22<>"",1,0),(U5="x"))*(G5-IFERROR(H5,0))/IFERROR(IF(COUNTIF(J5:U5,"x")=0,COUNTA(Besatzung!$B$11:$B$22),COUNTIF(J5:U5,"x")),1)+IF(COUNTIF(J5:U5,"x")=0,(Besatzung!$F$22="x"),(U5="x")*(Besatzung!$F$22="x"))*IFERROR(H5,0)/IFERROR(IF(COUNTIF(J5:U5,"x")=0,SUMPRODUCT((Besatzung!$B$11:$B$22<>"")*(Besatzung!$F$11:$F$22="x")),SUMPRODUCT((J5:U5="x")*(Besatzung!$F$11:$F$22="x"))),1))))),0))))
